##捕获、处理

try{
	//可能产生违例代码
}catch(Type var){
	
}

##掷出
被掷出的违例，必须在处理，因此，main()方法不能掷出违例，main()已经是程序最上层了。

- 在catch(Exception e){throw e}掷出
- 在void f() throws 

##Exception

基础违例，适用所有活动
- getMessage()获得详细信息
- toString()返回简单说明，包含详细信息
- printStackTrace()打印Throwable和其调用堆栈路径

##自定义违例

extends Exception

##限制

若一个方法产生了一种违例，当这个方法被覆盖时，不能产生其他的违例。覆盖方法，违例只能变少，不能增加。

##finally

无论违例是否产生，都执行的代码。